[2025-01-12T05:00:54.228+0000] {local_task_job_runner.py:123} INFO - ::group::Pre task execution logs
[2025-01-12T05:00:54.261+0000] {taskinstance.py:2612} INFO - Dependencies all met for dep_context=non-requeueable deps ti=<TaskInstance: fetch_and_store_books.insert_book_data manual__2025-01-12T05:00:41.014978+00:00 [queued]>
[2025-01-12T05:00:54.275+0000] {taskinstance.py:2612} INFO - Dependencies all met for dep_context=requeueable deps ti=<TaskInstance: fetch_and_store_books.insert_book_data manual__2025-01-12T05:00:41.014978+00:00 [queued]>
[2025-01-12T05:00:54.276+0000] {taskinstance.py:2865} INFO - Starting attempt 1 of 2
[2025-01-12T05:00:54.311+0000] {taskinstance.py:2888} INFO - Executing <Task(PythonOperator): insert_book_data> on 2025-01-12 05:00:41.014978+00:00
[2025-01-12T05:00:54.333+0000] {warnings.py:112} WARNING - /home/***/.local/lib/python3.12/site-packages/***/task/task_runner/standard_task_runner.py:70: DeprecationWarning: This process (pid=171) is multi-threaded, use of fork() may lead to deadlocks in the child.
  pid = os.fork()

[2025-01-12T05:00:54.337+0000] {standard_task_runner.py:72} INFO - Started process 173 to run task
[2025-01-12T05:00:54.335+0000] {standard_task_runner.py:104} INFO - Running: ['***', 'tasks', 'run', 'fetch_and_store_books', 'insert_book_data', 'manual__2025-01-12T05:00:41.014978+00:00', '--job-id', '153', '--raw', '--subdir', 'DAGS_FOLDER/app.py', '--cfg-path', '/tmp/tmp5ujna8jl']
[2025-01-12T05:00:54.346+0000] {standard_task_runner.py:105} INFO - Job 153: Subtask insert_book_data
[2025-01-12T05:00:54.439+0000] {task_command.py:467} INFO - Running <TaskInstance: fetch_and_store_books.insert_book_data manual__2025-01-12T05:00:41.014978+00:00 [running]> on host 58631913095f
[2025-01-12T05:00:54.597+0000] {taskinstance.py:3131} INFO - Exporting env vars: AIRFLOW_CTX_DAG_OWNER='***' AIRFLOW_CTX_DAG_ID='fetch_and_store_books' AIRFLOW_CTX_TASK_ID='insert_book_data' AIRFLOW_CTX_EXECUTION_DATE='2025-01-12T05:00:41.014978+00:00' AIRFLOW_CTX_TRY_NUMBER='1' AIRFLOW_CTX_DAG_RUN_ID='manual__2025-01-12T05:00:41.014978+00:00'
[2025-01-12T05:00:54.598+0000] {logging_mixin.py:190} INFO - Task instance is in running state
[2025-01-12T05:00:54.599+0000] {logging_mixin.py:190} INFO -  Previous state of the Task instance: queued
[2025-01-12T05:00:54.600+0000] {logging_mixin.py:190} INFO - Current task name:insert_book_data state:running start_date:2025-01-12 05:00:54.262096+00:00
[2025-01-12T05:00:54.600+0000] {logging_mixin.py:190} INFO - Dag name:fetch_and_store_books and current dag run status:running
[2025-01-12T05:00:54.601+0000] {taskinstance.py:731} INFO - ::endgroup::
[2025-01-12T05:00:54.621+0000] {base.py:84} INFO - Retrieving connection 'books_connection'
[2025-01-12T05:00:54.626+0000] {sql.py:509} INFO - Running statement: 
    INSERT INTO books (title, price, rating)
    VALUES (%s, %s, %s)
    ON CONFLICT (title) DO NOTHING; -- Skip duplicates
    , parameters: ("It's Only the Himalayas", 'Â£45.17', 'Two')
[2025-01-12T05:00:54.629+0000] {taskinstance.py:3310} ERROR - Task failed with exception
Traceback (most recent call last):
  File "/home/airflow/.local/lib/python3.12/site-packages/airflow/models/taskinstance.py", line 767, in _execute_task
    result = _execute_callable(context=context, **execute_callable_kwargs)
             ^^^^^^^^^^^^^^^^^^^^^^^^^^^^^^^^^^^^^^^^^^^^^^^^^^^^^^^^^^^^^
  File "/home/airflow/.local/lib/python3.12/site-packages/airflow/models/taskinstance.py", line 733, in _execute_callable
    return ExecutionCallableRunner(
           ^^^^^^^^^^^^^^^^^^^^^^^^
  File "/home/airflow/.local/lib/python3.12/site-packages/airflow/utils/operator_helpers.py", line 252, in run
    return self.func(*args, **kwargs)
           ^^^^^^^^^^^^^^^^^^^^^^^^^^
  File "/home/airflow/.local/lib/python3.12/site-packages/airflow/models/baseoperator.py", line 406, in wrapper
    return func(self, *args, **kwargs)
           ^^^^^^^^^^^^^^^^^^^^^^^^^^^
  File "/home/airflow/.local/lib/python3.12/site-packages/airflow/operators/python.py", line 238, in execute
    return_value = self.execute_callable()
                   ^^^^^^^^^^^^^^^^^^^^^^^
  File "/home/airflow/.local/lib/python3.12/site-packages/airflow/operators/python.py", line 256, in execute_callable
    return runner.run(*self.op_args, **self.op_kwargs)
           ^^^^^^^^^^^^^^^^^^^^^^^^^^^^^^^^^^^^^^^^^^^
  File "/home/airflow/.local/lib/python3.12/site-packages/airflow/utils/operator_helpers.py", line 252, in run
    return self.func(*args, **kwargs)
           ^^^^^^^^^^^^^^^^^^^^^^^^^^
  File "/opt/airflow/dags/app.py", line 91, in insert_book_data_into_postgres
    postgres_hook.run(insert_query, parameters=(book['Title'], book['Price'], book['Rating']))
  File "/home/airflow/.local/lib/python3.12/site-packages/airflow/providers/common/sql/hooks/sql.py", line 456, in run
    self._run_command(cur, sql_statement, parameters)
  File "/home/airflow/.local/lib/python3.12/site-packages/airflow/providers/common/sql/hooks/sql.py", line 512, in _run_command
    cur.execute(sql_statement, parameters)
psycopg2.errors.InvalidColumnReference: there is no unique or exclusion constraint matching the ON CONFLICT specification

[2025-01-12T05:00:54.654+0000] {logging_mixin.py:190} INFO - Task instance in failure state
[2025-01-12T05:00:54.656+0000] {logging_mixin.py:190} INFO - Task start:2025-01-12 05:00:54.262096+00:00 end:2025-01-12 05:00:54.652297+00:00 duration:0.390201
[2025-01-12T05:00:54.657+0000] {logging_mixin.py:190} INFO - Task:<Task(PythonOperator): insert_book_data> dag:<DAG: fetch_and_store_books> dagrun:<DagRun fetch_and_store_books @ 2025-01-12 05:00:41.014978+00:00: manual__2025-01-12T05:00:41.014978+00:00, state:running, queued_at: 2025-01-12 05:00:41.044418+00:00. externally triggered: True>
[2025-01-12T05:00:54.657+0000] {logging_mixin.py:190} INFO - Failure caused by there is no unique or exclusion constraint matching the ON CONFLICT specification
[2025-01-12T05:00:54.658+0000] {taskinstance.py:1225} INFO - Marking task as UP_FOR_RETRY. dag_id=fetch_and_store_books, task_id=insert_book_data, run_id=manual__2025-01-12T05:00:41.014978+00:00, execution_date=20250112T050041, start_date=20250112T050054, end_date=20250112T050054
[2025-01-12T05:00:54.715+0000] {taskinstance.py:340} INFO - ::group::Post task execution logs
[2025-01-12T05:00:54.724+0000] {standard_task_runner.py:124} ERROR - Failed to execute job 153 for task insert_book_data (there is no unique or exclusion constraint matching the ON CONFLICT specification
; 173)
Traceback (most recent call last):
  File "/home/airflow/.local/lib/python3.12/site-packages/airflow/task/task_runner/standard_task_runner.py", line 117, in _start_by_fork
    ret = args.func(args, dag=self.dag)
          ^^^^^^^^^^^^^^^^^^^^^^^^^^^^^
  File "/home/airflow/.local/lib/python3.12/site-packages/airflow/cli/cli_config.py", line 49, in command
    return func(*args, **kwargs)
           ^^^^^^^^^^^^^^^^^^^^^
  File "/home/airflow/.local/lib/python3.12/site-packages/airflow/utils/cli.py", line 115, in wrapper
    return f(*args, **kwargs)
           ^^^^^^^^^^^^^^^^^^
  File "/home/airflow/.local/lib/python3.12/site-packages/airflow/cli/commands/task_command.py", line 483, in task_run
    task_return_code = _run_task_by_selected_method(args, _dag, ti)
                       ^^^^^^^^^^^^^^^^^^^^^^^^^^^^^^^^^^^^^^^^^^^^
  File "/home/airflow/.local/lib/python3.12/site-packages/airflow/cli/commands/task_command.py", line 256, in _run_task_by_selected_method
    return _run_raw_task(args, ti)
           ^^^^^^^^^^^^^^^^^^^^^^^
  File "/home/airflow/.local/lib/python3.12/site-packages/airflow/cli/commands/task_command.py", line 341, in _run_raw_task
    return ti._run_raw_task(
           ^^^^^^^^^^^^^^^^^
  File "/home/airflow/.local/lib/python3.12/site-packages/airflow/utils/session.py", line 97, in wrapper
    return func(*args, session=session, **kwargs)
           ^^^^^^^^^^^^^^^^^^^^^^^^^^^^^^^^^^^^^^
  File "/home/airflow/.local/lib/python3.12/site-packages/airflow/models/taskinstance.py", line 3004, in _run_raw_task
    return _run_raw_task(
           ^^^^^^^^^^^^^^
  File "/home/airflow/.local/lib/python3.12/site-packages/airflow/models/taskinstance.py", line 273, in _run_raw_task
    TaskInstance._execute_task_with_callbacks(
  File "/home/airflow/.local/lib/python3.12/site-packages/airflow/models/taskinstance.py", line 3158, in _execute_task_with_callbacks
    result = self._execute_task(context, task_orig)
             ^^^^^^^^^^^^^^^^^^^^^^^^^^^^^^^^^^^^^^
  File "/home/airflow/.local/lib/python3.12/site-packages/airflow/models/taskinstance.py", line 3182, in _execute_task
    return _execute_task(self, context, task_orig)
           ^^^^^^^^^^^^^^^^^^^^^^^^^^^^^^^^^^^^^^^
  File "/home/airflow/.local/lib/python3.12/site-packages/airflow/models/taskinstance.py", line 767, in _execute_task
    result = _execute_callable(context=context, **execute_callable_kwargs)
             ^^^^^^^^^^^^^^^^^^^^^^^^^^^^^^^^^^^^^^^^^^^^^^^^^^^^^^^^^^^^^
  File "/home/airflow/.local/lib/python3.12/site-packages/airflow/models/taskinstance.py", line 733, in _execute_callable
    return ExecutionCallableRunner(
           ^^^^^^^^^^^^^^^^^^^^^^^^
  File "/home/airflow/.local/lib/python3.12/site-packages/airflow/utils/operator_helpers.py", line 252, in run
    return self.func(*args, **kwargs)
           ^^^^^^^^^^^^^^^^^^^^^^^^^^
  File "/home/airflow/.local/lib/python3.12/site-packages/airflow/models/baseoperator.py", line 406, in wrapper
    return func(self, *args, **kwargs)
           ^^^^^^^^^^^^^^^^^^^^^^^^^^^
  File "/home/airflow/.local/lib/python3.12/site-packages/airflow/operators/python.py", line 238, in execute
    return_value = self.execute_callable()
                   ^^^^^^^^^^^^^^^^^^^^^^^
  File "/home/airflow/.local/lib/python3.12/site-packages/airflow/operators/python.py", line 256, in execute_callable
    return runner.run(*self.op_args, **self.op_kwargs)
           ^^^^^^^^^^^^^^^^^^^^^^^^^^^^^^^^^^^^^^^^^^^
  File "/home/airflow/.local/lib/python3.12/site-packages/airflow/utils/operator_helpers.py", line 252, in run
    return self.func(*args, **kwargs)
           ^^^^^^^^^^^^^^^^^^^^^^^^^^
  File "/opt/airflow/dags/app.py", line 91, in insert_book_data_into_postgres
    postgres_hook.run(insert_query, parameters=(book['Title'], book['Price'], book['Rating']))
  File "/home/airflow/.local/lib/python3.12/site-packages/airflow/providers/common/sql/hooks/sql.py", line 456, in run
    self._run_command(cur, sql_statement, parameters)
  File "/home/airflow/.local/lib/python3.12/site-packages/airflow/providers/common/sql/hooks/sql.py", line 512, in _run_command
    cur.execute(sql_statement, parameters)
psycopg2.errors.InvalidColumnReference: there is no unique or exclusion constraint matching the ON CONFLICT specification

[2025-01-12T05:00:54.774+0000] {local_task_job_runner.py:266} INFO - Task exited with return code 1
[2025-01-12T05:00:54.791+0000] {taskinstance.py:3900} INFO - 0 downstream tasks scheduled from follow-on schedule check
[2025-01-12T05:00:54.795+0000] {local_task_job_runner.py:245} INFO - ::endgroup::
